<sdf version='1.9'>
  <world name='custom_world'>
    <gravity>0 0 -9.8</gravity>
    <magnetic_field>6e-06 2.3e-05 -4.2e-05</magnetic_field>
    <atmosphere type='adiabatic'/>
    <physics name='1ms' type='ignored'>
      <max_step_size>0.001</max_step_size>
      <real_time_factor>1000</real_time_factor>
      <real_time_update_rate>1000</real_time_update_rate>
    </physics>
    <plugin name='gz::sim::systems::Physics' filename='ignition-gazebo-physics-system'/>
    <plugin name='gz::sim::systems::UserCommands' filename='ignition-gazebo-user-commands-system'/>
    <plugin name='gz::sim::systems::SceneBroadcaster' filename='ignition-gazebo-scene-broadcaster-system'/>
    <scene>
      <ambient>0.4 0.4 0.4 1</ambient>
      <background>0.7 0.7 0.7 1</background>
      <shadows>true</shadows>
    </scene>
    <model name='caixa'>
      <pose>0 0.5 0.125 0 -0 0</pose>
      <link name='box_link'>
        <inertial>
          <inertia>
            <ixx>0.16666</ixx>
            <ixy>0</ixy>
            <ixz>0</ixz>
            <iyy>0.16666</iyy>
            <iyz>0</iyz>
            <izz>0.16666</izz>
          </inertia>
          <mass>1</mass>
          <pose>0 0 0 0 -0 0</pose>
        </inertial>
        <collision name='box_collision'>
          <geometry>
            <box>
              <size>0.3 0.3 0.25</size>
            </box>
          </geometry>
          <surface>
            <friction>
              <ode/>
            </friction>
            <bounce/>
            <contact/>
          </surface>
        </collision>
        <visual name='box_visual'>
          <geometry>
            <box>
              <size>0.3 0.3 0.25</size>
            </box>
          </geometry>
          <material>
            <ambient>0.3 0.3 0.3 1</ambient>
            <diffuse>0.7 0.7 0.7 1</diffuse>
            <specular>1 1 1 1</specular>
          </material>
        </visual>
        <pose>0 0 0 0 -0 0</pose>
        <enable_wind>false</enable_wind>
      </link>
      <static>true</static>
      <self_collide>false</self_collide>
    </model>
    <model name='towerbase'>
      <model name='towerbase'>
        <link name='towerbase_link'>
          <visual name='towerbase_0_towerbase_visual'>
            <pose>0.000000000 0.000000000 0.00000000 0.0000000000 0.000000000 0.000000000</pose>
            <geometry>
              <mesh>
                <uri>file:///home/leo/workspace/ur_gz/src/Universal_Robots_ROS2_Ignition_Simulation/ur_simulation_gz/sdf/models/towerbase/towerbase.dae</uri>
              </mesh>
            </geometry>
          </visual>
          <collision name='towerbase_0_towerbase_collision'>
            <pose>0.000000000 0.000000000 0.00000000 0.0000000000 0.000000000 0.000000000</pose>
            <geometry>
              <mesh>
                <uri>file:///home/leo/workspace/ur_gz/src/Universal_Robots_ROS2_Ignition_Simulation/ur_simulation_gz/sdf/models/towerbase/towerbase.stl</uri>
              </mesh>
            </geometry>
          </collision>
          <inertial>
            <pose>0.000000000 0.000000000 0.0065617668257740994001 0.000000000 0.000000000 0.00000000</pose>
            <mass>0.84404299999999999</mass>
            <inertia>
              <ixx>0.00072965699999999998</ixx>
              <ixy>0</ixy>
              <ixz>0</ixz>
              <iyy>0.0063466599999999996</iyy>
              <iyz>0</iyz>
              <izz>0.0069506699999999999</izz>
            </inertia>
          </inertial>
        </link>
        <pose>0.000000000 0.5000000 0.250000000 0.0 0.0 0.0</pose>
      </model>
      <pose>0 0 -0 0 -0 0</pose>
      <static>false</static>
      <self_collide>false</self_collide>
    </model>
    <model name='disk1'>
      <model name='disk1'>
        <link name='disk1_link'>
          <visual name='disk1_0_disk1_visual'>
            <pose>0.000000000 0.000000000 0.00000000 0.0000000000 0.000000000 0.000000000</pose>
            <geometry>
              <mesh>
                <uri>file://home/leo/workspace/ur_gz/src/Universal_Robots_ROS2_Ignition_Simulation/ur_simulation_gz/sdf/models/disk1/disk1.dae</uri>
              </mesh>
            </geometry>
          </visual>
          <collision name='disk1_0_disk1_collision'>
            <pose>0.000000000 0.000000000 0.00000000 0.0000000000 0.000000000 0.000000000</pose>
            <geometry>
              <mesh>
                <uri>file://home/leo/workspace/ur_gz/src/Universal_Robots_ROS2_Ignition_Simulation/ur_simulation_gz/sdf/models/disk1/disk1.stl</uri>
              </mesh>
            </geometry>
          </collision>
          <inertial>
            <pose>0.000000000 0.000000000 0.00000000 0.0000000000 0.000000000 0.000000000</pose>
            <mass>0.041045999999999999</mass>
            <inertia>
              <ixx>7.2783799999999999e-06</ixx>
              <ixy>0</ixy>
              <ixz>0</ixz>
              <iyy>7.2783799999999999e-06</iyy>
              <iyz>0</iyz>
              <izz>1.41491e-05</izz>
            </inertia>
          </inertial>
        </link>
        <pose>0.0000000 0.500000000 0.25100000000 0.000000000 0.000000000 0.000000000</pose>
      </model>
      <pose>-0.0927 -0.0002 -0.0114 -0.0008 0.3348 -0.0005</pose>
      <static>false</static>
      <self_collide>false</self_collide>
    </model>
    <model name='ur'>
      <joint name='base_joint' type='fixed'>
        <pose>0 0 0 0 -0 0</pose>
        <parent>world</parent>
        <child>base_link</child>
      </joint>
      <link name='base_link'>
        <pose>0 0 0 0 -0 0</pose>
        <inertial>
          <pose>0 0 0 0 -0 0</pose>
          <mass>2</mass>
          <inertia>
            <ixx>0.00305317</ixx>
            <ixy>0</ixy>
            <ixz>0</ixz>
            <iyy>0.00305317</iyy>
            <iyz>0</iyz>
            <izz>0.0056249999999999998</izz>
          </inertia>
        </inertial>
        <collision name='base_link_inertia_collision'>
          <pose>0 0 0 0 0 -2.449293598294706e-16</pose>
          <geometry>
            <mesh>
              <scale>1 1 1</scale>
              <uri>file:///home/leo/workspace/ur_gz/install/ur_description/share/ur_description/meshes/ur3e/collision/base.stl</uri>
            </mesh>
          </geometry>
        </collision>
        <visual name='base_link_inertia_visual'>
          <pose>0 0 0 0 0 -2.449293598294706e-16</pose>
          <geometry>
            <mesh>
              <scale>1 1 1</scale>
              <uri>file:///home/leo/workspace/ur_gz/install/ur_description/share/ur_description/meshes/ur3e/visual/base.dae</uri>
            </mesh>
          </geometry>
        </visual>
        <enable_wind>false</enable_wind>
      </link>
      <joint name='shoulder_pan_joint' type='revolute'>
        <pose>0 0 0 0 -0 0</pose>
        <parent>base_link</parent>
        <child>shoulder_link</child>
        <axis>
          <xyz>0 0 1</xyz>
          <limit>
            <lower>-6.2831900000000003</lower>
            <upper>6.2831900000000003</upper>
            <effort>56</effort>
            <velocity>3.1415899999999999</velocity>
            <stiffness>100000000</stiffness>
            <dissipation>1</dissipation>
          </limit>
          <dynamics>
            <spring_reference>0</spring_reference>
            <spring_stiffness>0</spring_stiffness>
            <damping>0</damping>
            <friction>0</friction>
          </dynamics>
        </axis>
      </joint>
      <link name='shoulder_link'>
        <pose>0 0 0.15185 0 -0 -3.14159</pose>
        <inertial>
          <pose>0 0 0 0 -0 0</pose>
          <mass>1.98</mass>
          <inertia>
            <ixx>0.0080122300000000004</ixx>
            <ixy>0</ixy>
            <ixz>0</ixz>
            <iyy>0.0080122300000000004</iyy>
            <iyz>0</iyz>
            <izz>0.0055687499999999999</izz>
          </inertia>
        </inertial>
        <collision name='shoulder_link_collision'>
          <pose>0 0 0 0 0 3.141592653589793</pose>
          <geometry>
            <mesh>
              <scale>1 1 1</scale>
              <uri>file:///home/leo/workspace/ur_gz/install/ur_description/share/ur_description/meshes/ur3e/collision/shoulder.stl</uri>
            </mesh>
          </geometry>
        </collision>
        <visual name='shoulder_link_visual'>
          <pose>0 0 0 0 0 3.141592653589793</pose>
          <geometry>
            <mesh>
              <scale>1 1 1</scale>
              <uri>file:///home/leo/workspace/ur_gz/install/ur_description/share/ur_description/meshes/ur3e/visual/shoulder.dae</uri>
            </mesh>
          </geometry>
        </visual>
        <enable_wind>false</enable_wind>
      </link>
      <joint name='shoulder_lift_joint' type='revolute'>
        <pose>-0 0 0 0 -0 0</pose>
        <parent>shoulder_link</parent>
        <child>upper_arm_link</child>
        <axis>
          <xyz>0 0 1</xyz>
          <limit>
            <lower>-6.2831900000000003</lower>
            <upper>6.2831900000000003</upper>
            <effort>56</effort>
            <velocity>3.1415899999999999</velocity>
            <stiffness>100000000</stiffness>
            <dissipation>1</dissipation>
          </limit>
          <dynamics>
            <spring_reference>0</spring_reference>
            <spring_stiffness>0</spring_stiffness>
            <damping>0</damping>
            <friction>0</friction>
          </dynamics>
        </axis>
      </joint>
      <link name='upper_arm_link'>
        <pose>0 0 0.15185 1.5708 1.57 -3.14159</pose>
        <inertial>
          <pose>-0.121825 0 0.12 0 1.5708 0</pose>
          <mass>3.4445000000000001</mass>
          <inertia>
            <ixx>0.0218841</ixx>
            <ixy>0</ixy>
            <ixz>0</ixz>
            <iyy>0.0218841</iyy>
            <iyz>0</iyz>
            <izz>0.0096876600000000007</izz>
          </inertia>
        </inertial>
        <collision name='upper_arm_link_collision'>
          <pose>0 0 0.12 1.570796326794896 0 -1.570796326794896</pose>
          <geometry>
            <mesh>
              <scale>1 1 1</scale>
              <uri>file:///home/leo/workspace/ur_gz/install/ur_description/share/ur_description/meshes/ur3e/collision/upperarm.stl</uri>
            </mesh>
          </geometry>
        </collision>
        <visual name='upper_arm_link_visual'>
          <pose>0 0 0.12 1.570796326794896 0 -1.570796326794896</pose>
          <geometry>
            <mesh>
              <scale>1 1 1</scale>
              <uri>file:///home/leo/workspace/ur_gz/install/ur_description/share/ur_description/meshes/ur3e/visual/upperarm.dae</uri>
            </mesh>
          </geometry>
        </visual>
        <enable_wind>false</enable_wind>
      </link>
      <joint name='elbow_joint' type='revolute'>
        <pose>0 0 -0 0 -0 0</pose>
        <parent>upper_arm_link</parent>
        <child>forearm_link</child>
        <axis>
          <xyz>0 0 1</xyz>
          <limit>
            <lower>-3.1415899999999999</lower>
            <upper>3.1415899999999999</upper>
            <effort>28</effort>
            <velocity>3.1415899999999999</velocity>
            <stiffness>100000000</stiffness>
            <dissipation>1</dissipation>
          </limit>
          <dynamics>
            <spring_reference>0</spring_reference>
            <spring_stiffness>0</spring_stiffness>
            <damping>0</damping>
            <friction>0</friction>
          </dynamics>
        </axis>
      </joint>
      <link name='forearm_link'>
        <pose>0.000194 0 0.3954 1.5708 1.57 -3.14159</pose>
        <inertial>
          <pose>-0.1066 0 0.027 0 1.5708 0</pose>
          <mass>1.4370000000000001</mass>
          <inertia>
            <ixx>0.0074639199999999998</ixx>
            <ixy>0</ixy>
            <ixz>0</ixz>
            <iyy>0.0074639199999999998</iyy>
            <iyz>0</iyz>
            <izz>0.0040415599999999996</izz>
          </inertia>
        </inertial>
        <collision name='forearm_link_collision'>
          <pose>0 0 0.027 1.570796326794896 0 -1.570796326794896</pose>
          <geometry>
            <mesh>
              <scale>1 1 1</scale>
              <uri>file:///home/leo/workspace/ur_gz/install/ur_description/share/ur_description/meshes/ur3e/collision/forearm.stl</uri>
            </mesh>
          </geometry>
        </collision>
        <visual name='forearm_link_visual'>
          <pose>0 0 0.027 1.570796326794896 0 -1.570796326794896</pose>
          <geometry>
            <mesh>
              <scale>1 1 1</scale>
              <uri>file:///home/leo/workspace/ur_gz/install/ur_description/share/ur_description/meshes/ur3e/visual/forearm.dae</uri>
            </mesh>
          </geometry>
        </visual>
        <enable_wind>false</enable_wind>
      </link>
      <joint name='wrist_1_joint' type='revolute'>
        <pose>0 -0 0 0 -0 0</pose>
        <parent>forearm_link</parent>
        <child>wrist_1_link</child>
        <axis>
          <xyz>0 0 1</xyz>
          <limit>
            <lower>-6.2831900000000003</lower>
            <upper>6.2831900000000003</upper>
            <effort>12</effort>
            <velocity>6.2831900000000003</velocity>
            <stiffness>100000000</stiffness>
            <dissipation>1</dissipation>
          </limit>
          <dynamics>
            <spring_reference>0</spring_reference>
            <spring_stiffness>0</spring_stiffness>
            <damping>0</damping>
            <friction>0</friction>
          </dynamics>
        </axis>
      </joint>
      <link name='wrist_1_link'>
        <pose>0.000364 0.13105 0.6086 -1.5708 0.001593 -0</pose>
        <inertial>
          <pose>0 0 0 0 -0 0</pose>
          <mass>0.871</mass>
          <inertia>
            <ixx>0.0022700400000000001</ixx>
            <ixy>0</ixy>
            <ixz>0</ixz>
            <iyy>0.0022700400000000001</iyy>
            <iyz>0</iyz>
            <izz>0.00244969</izz>
          </inertia>
        </inertial>
        <collision name='wrist_1_link_collision'>
          <pose>0 0 -0.104 1.570796326794896 0 0</pose>
          <geometry>
            <mesh>
              <scale>1 1 1</scale>
              <uri>file:///home/leo/workspace/ur_gz/install/ur_description/share/ur_description/meshes/ur3e/collision/wrist1.stl</uri>
            </mesh>
          </geometry>
        </collision>
        <visual name='wrist_1_link_visual'>
          <pose>0 0 -0.104 1.570796326794896 0 0</pose>
          <geometry>
            <mesh>
              <scale>1 1 1</scale>
              <uri>file:///home/leo/workspace/ur_gz/install/ur_description/share/ur_description/meshes/ur3e/visual/wrist1.dae</uri>
            </mesh>
          </geometry>
        </visual>
        <enable_wind>false</enable_wind>
      </link>
      <joint name='wrist_2_joint' type='revolute'>
        <pose>0 -0 0 0 -0 0</pose>
        <parent>wrist_1_link</parent>
        <child>wrist_2_link</child>
        <axis>
          <xyz>0 0 1</xyz>
          <limit>
            <lower>-6.2831900000000003</lower>
            <upper>6.2831900000000003</upper>
            <effort>12</effort>
            <velocity>6.2831900000000003</velocity>
            <stiffness>100000000</stiffness>
            <dissipation>1</dissipation>
          </limit>
          <dynamics>
            <spring_reference>0</spring_reference>
            <spring_stiffness>0</spring_stiffness>
            <damping>0</damping>
            <friction>0</friction>
          </dynamics>
        </axis>
      </joint>
      <link name='wrist_2_link'>
        <pose>0.0005 0.13105 0.69395 0 0.001593 0</pose>
        <inertial>
          <pose>0 0 0 0 -0 0</pose>
          <mass>0.80500000000000005</mass>
          <inertia>
            <ixx>0.0020980299999999999</ixx>
            <ixy>0</ixy>
            <ixz>0</ixz>
            <iyy>0.0020980299999999999</iyy>
            <iyz>0</iyz>
            <izz>0.00226406</izz>
          </inertia>
        </inertial>
        <collision name='wrist_2_link_collision'>
          <pose>0 0 -0.08535 0 0 0</pose>
          <geometry>
            <mesh>
              <scale>1 1 1</scale>
              <uri>file:///home/leo/workspace/ur_gz/install/ur_description/share/ur_description/meshes/ur3e/collision/wrist2.stl</uri>
            </mesh>
          </geometry>
        </collision>
        <visual name='wrist_2_link_visual'>
          <pose>0 0 -0.08535 0 0 0</pose>
          <geometry>
            <mesh>
              <scale>1 1 1</scale>
              <uri>file:///home/leo/workspace/ur_gz/install/ur_description/share/ur_description/meshes/ur3e/visual/wrist2.dae</uri>
            </mesh>
          </geometry>
        </visual>
        <enable_wind>false</enable_wind>
      </link>
      <joint name='wrist_3_joint' type='revolute'>
        <pose>0 0 0 0 -0 0</pose>
        <parent>wrist_2_link</parent>
        <child>wrist_3_link</child>
        <axis>
          <xyz>0 0 1</xyz>
          <limit>
            <lower>-6.2831900000000003</lower>
            <upper>6.2831900000000003</upper>
            <effort>12</effort>
            <velocity>6.2831900000000003</velocity>
            <stiffness>100000000</stiffness>
            <dissipation>1</dissipation>
          </limit>
          <dynamics>
            <spring_reference>0</spring_reference>
            <spring_stiffness>0</spring_stiffness>
            <damping>0</damping>
            <friction>0</friction>
          </dynamics>
        </axis>
      </joint>
      <link name='wrist_3_link'>
        <pose>0.0005 0.22315 0.69395 -1.5708 -1.56841 0</pose>
        <inertial>
          <pose>0 -0.000767 0.033294 0 -0 0</pose>
          <mass>1.15507</mass>
          <inertia>
            <ixx>0.00250293</ixx>
            <ixy>-1.08151e-07</ixy>
            <ixz>4.1196199999999999e-07</ixz>
            <iyy>0.0026922299999999999</iyy>
            <iyz>1.35605e-05</iyz>
            <izz>0.0010165599999999999</izz>
          </inertia>
        </inertial>
        <collision name='wrist_3_link_collision'>
          <pose>0 0 -0.0921 1.570796326794896 0 0</pose>
          <geometry>
            <mesh>
              <scale>1 1 1</scale>
              <uri>file:///home/leo/workspace/ur_gz/install/ur_description/share/ur_description/meshes/ur3e/collision/wrist3.stl</uri>
            </mesh>
          </geometry>
        </collision>
        <collision name='wrist_3_link_fixed_joint_lump__schunk_egh80_link_collision_1'>
          <pose>2.168404344971009e-19 -0.001000000000000026 -3.838075690598686e-17 2.775557561562891e-16 -5.551115123125785e-17 -3.141592653589793</pose>
          <geometry>
            <mesh>
              <scale>1 1 1</scale>
              <uri>file:///home/leo/workspace/ur_gz/install/ur_description/share/ur_description/meshes/schunk/collision/gripper_connector.stl</uri>
            </mesh>
          </geometry>
        </collision>
        <collision name='wrist_3_link_fixed_joint_lump__schunk_egh80_link_collision_2'>
          <pose>2.775557561562891e-17 -0.03642326917148208 0.07550365554862044 -1.343903524035633 -3.821043421368649e-16 -3.141592653589793</pose>
          <geometry>
            <mesh>
              <scale>1 1 1</scale>
              <uri>file:///home/leo/workspace/ur_gz/install/ur_description/share/ur_description/meshes/schunk/collision/etiqueta.stl</uri>
            </mesh>
          </geometry>
        </collision>
        <collision name='wrist_3_link_fixed_joint_lump__schunk_egh80_link_collision_3'>
          <pose>2.168404344971009e-19 -0.001000000000000026 -3.838075690598686e-17 2.775557561562891e-16 -5.551115123125785e-17 -3.141592653589793</pose>
          <geometry>
            <mesh>
              <scale>1 1 1</scale>
              <uri>file:///home/leo/workspace/ur_gz/install/ur_description/share/ur_description/meshes/schunk/collision/egh_80.stl</uri>
            </mesh>
          </geometry>
        </collision>
        <visual name='wrist_3_link_visual'>
          <pose>0 0 -0.0921 1.570796326794896 0 0</pose>
          <geometry>
            <mesh>
              <scale>1 1 1</scale>
              <uri>file:///home/leo/workspace/ur_gz/install/ur_description/share/ur_description/meshes/ur3e/visual/wrist3.dae</uri>
            </mesh>
          </geometry>
        </visual>
        <visual name='wrist_3_link_fixed_joint_lump__schunk_egh80_link_visual_1'>
          <pose>2.168404344971009e-19 -0.001000000000000026 2.168404344971009e-19 2.775557561562891e-16 -5.551115123125785e-17 -3.141592653589793</pose>
          <geometry>
            <mesh>
              <scale>1 1 1</scale>
              <uri>file:///home/leo/workspace/ur_gz/install/ur_description/share/ur_description/meshes/schunk/visual/gripper_connector.dae</uri>
            </mesh>
          </geometry>
          <material>
            <diffuse>0.627451 0.627451 0.627451 1</diffuse>
            <ambient>0.627451 0.627451 0.627451 1</ambient>
          </material>
        </visual>
        <visual name='wrist_3_link_fixed_joint_lump__schunk_egh80_link_visual_2'>
          <pose>2.775557561562891e-17 -0.03642326917148208 0.07550365554862044 -1.343903524035633 -3.821043421368649e-16 -3.141592653589793</pose>
          <geometry>
            <mesh>
              <scale>1 1 1</scale>
              <uri>file:///home/leo/workspace/ur_gz/install/ur_description/share/ur_description/meshes/schunk/visual/etiqueta.dae</uri>
            </mesh>
          </geometry>
          <material>
            <diffuse>0.862745 0.862745 0.862745 1</diffuse>
            <ambient>0.862745 0.862745 0.862745 1</ambient>
          </material>
        </visual>
        <visual name='wrist_3_link_fixed_joint_lump__schunk_egh80_link_visual_3'>
          <pose>2.168404344971009e-19 -0.001000000000000026 -3.838075690598686e-17 2.775557561562891e-16 -5.551115123125785e-17 -3.141592653589793</pose>
          <geometry>
            <mesh>
              <scale>1 1 1</scale>
              <uri>file:///home/leo/workspace/ur_gz/install/ur_description/share/ur_description/meshes/schunk/visual/egh_80.dae</uri>
            </mesh>
          </geometry>
          <material>
            <diffuse>0.862745 0.862745 0.862745 1</diffuse>
            <ambient>0.862745 0.862745 0.862745 1</ambient>
          </material>
        </visual>
        <enable_wind>false</enable_wind>
      </link>
      <joint name='dedo_dir_joint' type='prismatic'>
        <pose>-0 0 0 0 -0 0</pose>
        <parent>wrist_3_link</parent>
        <child>dedo_dir</child>
        <axis>
          <xyz>0 0 1</xyz>
          <limit>
            <lower>0</lower>
            <upper>0.040000000000000001</upper>
            <effort>1</effort>
            <velocity>0.080000000000000002</velocity>
            <stiffness>100000000</stiffness>
            <dissipation>1</dissipation>
          </limit>
          <dynamics>
            <spring_reference>0</spring_reference>
            <spring_stiffness>0</spring_stiffness>
            <damping>0</damping>
            <friction>0</friction>
          </dynamics>
        </axis>
      </joint>
      <link name='dedo_dir'>
        <pose>-0.003155 0.33235 0.681441 0 0.002382 0</pose>
        <inertial>
          <pose>0.002983 0.027802 0.034872 0 -0 0</pose>
          <mass>0.074377100000000002</mass>
          <inertia>
            <ixx>5.2720399999999998e-05</ixx>
            <ixy>1.3456699999999999e-06</ixy>
            <ixz>5.2493999999999999e-07</ixz>
            <iyy>1.0703899999999999e-05</iyy>
            <iyz>-7.3634399999999999e-06</iyz>
            <izz>4.94952e-05</izz>
          </inertia>
        </inertial>
        <collision name='dedo_dir_collision'>
          <pose>0.002324999999999978 0.08007769391666489 0.03195000000000001 3.141592653589793 5.610667679425537e-47 -3.141592653589793</pose>
          <geometry>
            <mesh>
              <scale>1 1 1</scale>
              <uri>file:///home/leo/workspace/ur_gz/install/ur_description/share/ur_description/meshes/schunk/collision/almofada.stl</uri>
            </mesh>
          </geometry>
        </collision>
        <collision name='dedo_dir_collision_1'>
          <pose>0.001825000000000038 0.03329999999999977 0.04070000000000001 0 1.570796326794897 9.244463733061492e-33</pose>
          <geometry>
            <mesh>
              <scale>1 1 1</scale>
              <uri>file:///home/leo/workspace/ur_gz/install/ur_description/share/ur_description/meshes/schunk/collision/falanginha.stl</uri>
            </mesh>
          </geometry>
        </collision>
        <collision name='dedo_dir_collision_2'>
          <pose>0.002624999999999943 0.0332999999999998 0.04070000000000001 0 1.570796326794897 9.244463733061492e-33</pose>
          <geometry>
            <mesh>
              <scale>1 1 1</scale>
              <uri>file:///home/leo/workspace/ur_gz/install/ur_description/share/ur_description/meshes/schunk/collision/falange.stl</uri>
            </mesh>
          </geometry>
        </collision>
        <collision name='dedo_dir_collision_3'>
          <pose>0.002324999999999977 0.06529999999999977 0.04070000000000001 0 1.570796326794897 9.244463733061492e-33</pose>
          <geometry>
            <mesh>
              <scale>1 1 1</scale>
              <uri>file:///home/leo/workspace/ur_gz/install/ur_description/share/ur_description/meshes/schunk/collision/falangeta.stl</uri>
            </mesh>
          </geometry>
        </collision>
        <collision name='dedo_dir_collision_4'>
          <pose>0.002625000000000001 0.01600000000000001 0.04150000000000001 0 1.570796326794897 9.244463733061492e-33</pose>
          <geometry>
            <mesh>
              <scale>1 1 1</scale>
              <uri>file:///home/leo/workspace/ur_gz/install/ur_description/share/ur_description/meshes/schunk/collision/guia_dedo.stl</uri>
            </mesh>
          </geometry>
        </collision>
        <visual name='dedo_dir_visual'>
          <pose>0.002324999999999978 0.08007769391666489 0.03195000000000001 3.141592653589793 0 -3.141592653589793</pose>
          <geometry>
            <mesh>
              <scale>1 1 1</scale>
              <uri>file:///home/leo/workspace/ur_gz/install/ur_description/share/ur_description/meshes/schunk/visual/almofada.dae</uri>
            </mesh>
          </geometry>
        </visual>
        <visual name='dedo_dir_visual_1'>
          <pose>0.001825000000000038 0.03329999999999977 0.04070000000000001 0 1.570796326794897 9.244463733061492e-33</pose>
          <geometry>
            <mesh>
              <scale>1 1 1</scale>
              <uri>file:///home/leo/workspace/ur_gz/install/ur_description/share/ur_description/meshes/schunk/visual/falanginha.dae</uri>
            </mesh>
          </geometry>
          <material>
            <diffuse>1 1 1 1</diffuse>
            <ambient>1 1 1 1</ambient>
          </material>
        </visual>
        <visual name='dedo_dir_visual_2'>
          <pose>0.002624999999999943 0.0332999999999998 0.04070000000000001 0 1.570796326794897 9.244463733061492e-33</pose>
          <geometry>
            <mesh>
              <scale>1 1 1</scale>
              <uri>file:///home/leo/workspace/ur_gz/install/ur_description/share/ur_description/meshes/schunk/visual/falange.dae</uri>
            </mesh>
          </geometry>
          <material>
            <diffuse>1 1 1 1</diffuse>
            <ambient>1 1 1 1</ambient>
          </material>
        </visual>
        <visual name='dedo_dir_visual_3'>
          <pose>0.002324999999999977 0.06529999999999977 0.04070000000000001 0 1.570796326794897 9.244463733061492e-33</pose>
          <geometry>
            <mesh>
              <scale>1 1 1</scale>
              <uri>file:///home/leo/workspace/ur_gz/install/ur_description/share/ur_description/meshes/schunk/visual/falangeta.dae</uri>
            </mesh>
          </geometry>
          <material>
            <diffuse>1 1 1 1</diffuse>
            <ambient>1 1 1 1</ambient>
          </material>
        </visual>
        <visual name='dedo_dir_visual_4'>
          <pose>0.002625000000000001 0.01600000000000001 0.04150000000000001 0 1.570796326794897 9.244463733061492e-33</pose>
          <geometry>
            <mesh>
              <scale>1 1 1</scale>
              <uri>file:///home/leo/workspace/ur_gz/install/ur_description/share/ur_description/meshes/schunk/visual/guia_dedo.dae</uri>
            </mesh>
          </geometry>
          <material>
            <diffuse>0.289216 0.289216 0.289216 1</diffuse>
            <ambient>0.289216 0.289216 0.289216 1</ambient>
          </material>
        </visual>
        <enable_wind>false</enable_wind>
      </link>
      <joint name='dedo_esq_joint' type='prismatic'>
        <pose>0 0 -0 0 -0 0</pose>
        <parent>wrist_3_link</parent>
        <child>dedo_esq</child>
        <axis>
          <xyz>-0 0 1</xyz>
          <limit>
            <lower>0</lower>
            <upper>0.040000000000000001</upper>
            <effort>1</effort>
            <velocity>0.080000000000000002</velocity>
            <stiffness>100000000</stiffness>
            <dissipation>1</dissipation>
          </limit>
          <dynamics>
            <spring_reference>0</spring_reference>
            <spring_stiffness>0</spring_stiffness>
            <damping>0</damping>
            <friction>0</friction>
          </dynamics>
        </axis>
      </joint>
      <link name='dedo_esq'>
        <pose>0.002131 0.33235 0.696429 -3.14159 -0.002381 3.14159</pose>
        <inertial>
          <pose>0.002983 0.027802 0.034872 0 -0 0</pose>
          <mass>0.074377100000000002</mass>
          <inertia>
            <ixx>5.2720399999999998e-05</ixx>
            <ixy>1.3456699999999999e-06</ixy>
            <ixz>5.2493999999999999e-07</ixz>
            <iyy>1.0703899999999999e-05</iyy>
            <iyz>-7.3634399999999999e-06</iyz>
            <izz>4.94952e-05</izz>
          </inertia>
        </inertial>
        <collision name='dedo_esq_collision'>
          <pose>0.002324999999999967 0.0800776939166649 0.03194999999999999 3.141592653589793 0 -3.141592653589793</pose>
          <geometry>
            <mesh>
              <scale>1 1 1</scale>
              <uri>file:///home/leo/workspace/ur_gz/install/ur_description/share/ur_description/meshes/schunk/collision/almofada.stl</uri>
            </mesh>
          </geometry>
        </collision>
        <collision name='dedo_esq_collision_1'>
          <pose>0.001825000000000027 0.03329999999999976 0.04070000000000003 0 1.570796326794897 0</pose>
          <geometry>
            <mesh>
              <scale>1 1 1</scale>
              <uri>file:///home/leo/workspace/ur_gz/install/ur_description/share/ur_description/meshes/schunk/collision/falanginha.stl</uri>
            </mesh>
          </geometry>
        </collision>
        <collision name='dedo_esq_collision_2'>
          <pose>0.002624999999999937 0.03329999999999976 0.04070000000000001 0 1.570796326794897 0</pose>
          <geometry>
            <mesh>
              <scale>1 1 1</scale>
              <uri>file:///home/leo/workspace/ur_gz/install/ur_description/share/ur_description/meshes/schunk/collision/falange.stl</uri>
            </mesh>
          </geometry>
        </collision>
        <collision name='dedo_esq_collision_3'>
          <pose>0.002324999999999971 0.06529999999999968 0.04070000000000001 0 1.570796326794897 0</pose>
          <geometry>
            <mesh>
              <scale>1 1 1</scale>
              <uri>file:///home/leo/workspace/ur_gz/install/ur_description/share/ur_description/meshes/schunk/visual/falangeta.dae</uri>
            </mesh>
          </geometry>
        </collision>
        <collision name='dedo_esq_collision_4'>
          <pose>0.002625000000000001 0.016 0.0415 0 1.570796326794897 0</pose>
          <geometry>
            <mesh>
              <scale>1 1 1</scale>
              <uri>file:///home/leo/workspace/ur_gz/install/ur_description/share/ur_description/meshes/schunk/collision/guia_dedo.stl</uri>
            </mesh>
          </geometry>
        </collision>
        <visual name='dedo_esq_visual'>
          <pose>0.002324999999999967 0.0800776939166649 0.03194999999999999 3.141592653589793 0 -3.141592653589793</pose>
          <geometry>
            <mesh>
              <scale>1 1 1</scale>
              <uri>file:///home/leo/workspace/ur_gz/install/ur_description/share/ur_description/meshes/schunk/visual/almofada.dae</uri>
            </mesh>
          </geometry>
        </visual>
        <visual name='dedo_esq_visual_1'>
          <pose>0.001825000000000027 0.03329999999999976 0.04070000000000003 0 1.570796326794897 0</pose>
          <geometry>
            <mesh>
              <scale>1 1 1</scale>
              <uri>file:///home/leo/workspace/ur_gz/install/ur_description/share/ur_description/meshes/schunk/visual/falanginha.dae</uri>
            </mesh>
          </geometry>
        </visual>
        <visual name='dedo_esq_visual_2'>
          <pose>0.002624999999999937 0.03329999999999976 0.04070000000000001 0 1.570796326794897 0</pose>
          <geometry>
            <mesh>
              <scale>1 1 1</scale>
              <uri>file:///home/leo/workspace/ur_gz/install/ur_description/share/ur_description/meshes/schunk/visual/falange.dae</uri>
            </mesh>
          </geometry>
        </visual>
        <visual name='dedo_esq_visual_3'>
          <pose>0.002324999999999971 0.06529999999999968 0.04070000000000001 0 1.570796326794897 0</pose>
          <geometry>
            <mesh>
              <scale>1 1 1</scale>
              <uri>file:///home/leo/workspace/ur_gz/install/ur_description/share/ur_description/meshes/schunk/visual/falangeta.dae</uri>
            </mesh>
          </geometry>
        </visual>
        <visual name='dedo_esq_visual_4'>
          <pose>0.002625000000000001 0.016 0.0415 0 1.570796326794897 0</pose>
          <geometry>
            <mesh>
              <scale>1 1 1</scale>
              <uri>file:///home/leo/workspace/ur_gz/install/ur_description/share/ur_description/meshes/schunk/visual/guia_dedo.dae</uri>
            </mesh>
          </geometry>
        </visual>
        <enable_wind>false</enable_wind>
      </link>
      <plugin name='ign_ros2_control::IgnitionROS2ControlPlugin' filename='libign_ros2_control-system.so'>
        <parameters>/home/leo/workspace/ur_gz/install/ur_simulation_gz/share/ur_simulation_gz/config/ur_controllers.yaml</parameters>
        <controller_manager_node_name>controller_manager</controller_manager_node_name>
      </plugin>
      <frame name='base_link-base_fixed_joint' attached_to='base_link'>
        <pose>0 0 0 0 -0 3.14159</pose>
      </frame>
      <frame name='base' attached_to='base_link-base_fixed_joint'/>
      <frame name='base_link-base_link_inertia' attached_to='base_link'>
        <pose>0 0 0 0 -0 3.14159</pose>
      </frame>
      <frame name='base_link_inertia' attached_to='base_link-base_link_inertia'/>
      <frame name='flange-tool0' attached_to='flange'>
        <pose>0 0 0 1.5708 -0 1.5708</pose>
      </frame>
      <frame name='tool0' attached_to='flange-tool0'/>
      <frame name='gripper_base_joint' attached_to='flange'>
        <pose>0 0 0 -1.5708 -0 -1.5708</pose>
      </frame>
      <frame name='schunk_egh80_link' attached_to='gripper_base_joint'/>
      <frame name='tool0-tcp' attached_to='flange'>
        <pose>0.1814 0 0 1.5708 -0 1.5708</pose>
      </frame>
      <frame name='tcp' attached_to='tool0-tcp'/>
      <frame name='wrist_3-flange' attached_to='wrist_3_link'>
        <pose>0 0 0 -1.5708 -1.5708 0</pose>
      </frame>
      <frame name='flange' attached_to='wrist_3-flange'/>
      <pose>0 0 0 0 -0 0</pose>
      <static>false</static>
      <self_collide>false</self_collide>
    </model>
    <light name='directionallight' type='directional'>
      <pose>-0.169552 0.472756 2 0 -0 0</pose>
      <cast_shadows>true</cast_shadows>
      <intensity>1</intensity>
      <direction>0 0 -1</direction>
      <diffuse>0.8 0.8 0.8 1</diffuse>
      <specular>0.2 0.2 0.2 1</specular>
      <attenuation>
        <range>1000</range>
        <linear>0.01</linear>
        <constant>0.90000000000000002</constant>
        <quadratic>0.001</quadratic>
      </attenuation>
      <spot>
        <inner_angle>0</inner_angle>
        <outer_angle>0</outer_angle>
        <falloff>0</falloff>
      </spot>
    </light>
  </world>
</sdf>
